Workbook

Sheet Live Calculator
B1: 2026 WORLD CUP — LIVE ODDS & DRAW-PROBABILITY CALCULATOR
B2: Type into the YELLOW cells only. Green cells are the answer. Prices are 0–1 (e.g. 27¢ = 0.27). Leave market prices blank to see model-only.
B4: INPUTS | E4: RESULTS
B5: Home team | C5: Brazil | E5: Outcome | F5: Model | G5: Market | H5: Blended (fair) | I5: Price paid | J5: Edge
B6: Away team | C6: Haiti | E6: Home win | F6: =$C$53 | G6: =$C$58 | H6: =$C$61/$C$64 | I6: =$C$10 | J6: =$C$61/$C$64-$C$10
B7: Home score (now) | C7: 0 | E7: Draw | F7: =$C$54 | G7: =$C$59 | H7: =$C$62/$C$64 | I7: =$C$11 | J7: =$C$62/$C$64-$C$11
B8: Away score (now) | C8: 0 | E8: Away win | F8: =$C$55 | G8: =$C$60 | H8: =$C$63/$C$64 | I8: =$C$12 | J8: =$C$63/$C$64-$C$12
B9: Minute (0–94) | C9: 0
B10: Polymarket: Home price | C10: 0
B11: Polymarket: Draw price | C11: 0 | E11: PROBABILITY OF A DRAW (blended fair)
B12: Polymarket: Away price | C12: 0 | E12: =TEXT($C$62/$C$64,"0.0%") | H12: =IF(($C$62/$C$64)-$C$11>0.04,"DRAW UNDERPRICED → value BUY",IF(($C$62/$C$64)-$C$11<-0.04,"DRAW OVERPRICED → avoid / SELL",IF($C$11=0,"(enter draw price for a verdict)","DRAW fairly priced → no edge")))
B13: Blend weight on market | C13: 0.6
E14: =CONCATENATE("Model draw ",TEXT($C$54,"0.0%")," | Market draw ",TEXT($C$59,"0.0%")," | You pay ",TEXT($C$11*100,"0"),"¢ | Fair ",TEXT($C$62/$C$64,"0.0%"))
B16: ENGINE (auto — do not edit)
B17: atk_home | C17: =VLOOKUP($C$5,Ratings!$A:$C,2,FALSE)
B18: dfn_home | C18: =VLOOKUP($C$5,Ratings!$A:$C,3,FALSE)
B19: atk_away | C19: =VLOOKUP($C$6,Ratings!$A:$C,2,FALSE)
B20: dfn_away | C20: =VLOOKUP($C$6,Ratings!$A:$C,3,FALSE)
B21: host_home | C21: =IF(ISNUMBER(MATCH($C$5,Ratings!$H:$H,0)),1,0)
B22: host_away | C22: =IF(ISNUMBER(MATCH($C$6,Ratings!$H:$H,0)),1,0)
B23: xG home (pre) | C23: =EXP(Ratings!$F$1+$C$17-$C$20+Ratings!$F$2*$C$21)
B24: xG away (pre) | C24: =EXP(Ratings!$F$1+$C$19-$C$18+Ratings!$F$2*$C$22)
B25: mins-left frac | C25: =MAX(0,(94-$C$9)/90)
B26: remaining xG home | C26: =$C$23*$C$25
B27: remaining xG away | C27: =$C$24*$C$25
E30: i\j | F30: 0 | G30: 1 | H30: 2 | I30: 3 | J30: 4 | K30: 5 | L30: 6 | M30: 7 | N30: 8
E31: 0 | F31: =POISSON.DIST($E31,$C$27,FALSE)*POISSON.DIST(F$30,$C$28,FALSE) | G31: =POISSON.DIST($E31,$C$27,FALSE)*POISSON.DIST(G$30,$C$28,FALSE) | H31: =POISSON.DIST($E31,$C$27,FALSE)*POISSON.DIST(H$30,$C$28,FALSE) | I31: =POISSON.DIST($E31,$C$27,FALSE)*POISSON.DIST(I$30,$C$28,FALSE) | J31: =POISSON.DIST($E31,$C$27,FALSE)*POISSON.DIST(J$30,$C$28,FALSE) | K31: =POISSON.DIST($E31,$C$27,FALSE)*POISSON.DIST(K$30,$C$28,FALSE) | L31: =POISSON.DIST($E31,$C$27,FALSE)*POISSON.DIST(L$30,$C$28,FALSE) | M31: =POISSON.DIST($E31,$C$27,FALSE)*POISSON.DIST(M$30,$C$28,FALSE) | N31: =POISSON.DIST($E31,$C$27,FALSE)*POISSON.DIST(N$30,$C$28,FALSE)
E32: 1 | F32: =POISSON.DIST($E32,$C$27,FALSE)*POISSON.DIST(F$30,$C$28,FALSE) | G32: =POISSON.DIST($E32,$C$27,FALSE)*POISSON.DIST(G$30,$C$28,FALSE) | H32: =POISSON.DIST($E32,$C$27,FALSE)*POISSON.DIST(H$30,$C$28,FALSE) | I32: =POISSON.DIST($E32,$C$27,FALSE)*POISSON.DIST(I$30,$C$28,FALSE) | J32: =POISSON.DIST($E32,$C$27,FALSE)*POISSON.DIST(J$30,$C$28,FALSE) | K32: =POISSON.DIST($E32,$C$27,FALSE)*POISSON.DIST(K$30,$C$28,FALSE) | L32: =POISSON.DIST($E32,$C$27,FALSE)*POISSON.DIST(L$30,$C$28,FALSE) | M32: =POISSON.DIST($E32,$C$27,FALSE)*POISSON.DIST(M$30,$C$28,FALSE) | N32: =POISSON.DIST($E32,$C$27,FALSE)*POISSON.DIST(N$30,$C$28,FALSE)
E33: 2 | F33: =POISSON.DIST($E33,$C$27,FALSE)*POISSON.DIST(F$30,$C$28,FALSE) | G33: =POISSON.DIST($E33,$C$27,FALSE)*POISSON.DIST(G$30,$C$28,FALSE) | H33: =POISSON.DIST($E33,$C$27,FALSE)*POISSON.DIST(H$30,$C$28,FALSE) | I33: =POISSON.DIST($E33,$C$27,FALSE)*POISSON.DIST(I$30,$C$28,FALSE) | J33: =POISSON.DIST($E33,$C$27,FALSE)*POISSON.DIST(J$30,$C$28,FALSE) | K33: =POISSON.DIST($E33,$C$27,FALSE)*POISSON.DIST(K$30,$C$28,FALSE) | L33: =POISSON.DIST($E33,$C$27,FALSE)*POISSON.DIST(L$30,$C$28,FALSE) | M33: =POISSON.DIST($E33,$C$27,FALSE)*POISSON.DIST(M$30,$C$28,FALSE) | N33: =POISSON.DIST($E33,$C$27,FALSE)*POISSON.DIST(N$30,$C$28,FALSE)
E34: 3 | F34: =POISSON.DIST($E34,$C$27,FALSE)*POISSON.DIST(F$30,$C$28,FALSE) | G34: =POISSON.DIST($E34,$C$27,FALSE)*POISSON.DIST(G$30,$C$28,FALSE) | H34: =POISSON.DIST($E34,$C$27,FALSE)*POISSON.DIST(H$30,$C$28,FALSE) | I34: =POISSON.DIST($E34,$C$27,FALSE)*POISSON.DIST(I$30,$C$28,FALSE) | J34: =POISSON.DIST($E34,$C$27,FALSE)*POISSON.DIST(J$30,$C$28,FALSE) | K34: =POISSON.DIST($E34,$C$27,FALSE)*POISSON.DIST(K$30,$C$28,FALSE) | L34: =POISSON.DIST($E34,$C$27,FALSE)*POISSON.DIST(L$30,$C$28,FALSE) | M34: =POISSON.DIST($E34,$C$27,FALSE)*POISSON.DIST(M$30,$C$28,FALSE) | N34: =POISSON.DIST($E34,$C$27,FALSE)*POISSON.DIST(N$30,$C$28,FALSE)
E35: 4 | F35: =POISSON.DIST($E35,$C$27,FALSE)*POISSON.DIST(F$30,$C$28,FALSE) | G35: =POISSON.DIST($E35,$C$27,FALSE)*POISSON.DIST(G$30,$C$28,FALSE) | H35: =POISSON.DIST($E35,$C$27,FALSE)*POISSON.DIST(H$30,$C$28,FALSE) | I35: =POISSON.DIST($E35,$C$27,FALSE)*POISSON.DIST(I$30,$C$28,FALSE) | J35: =POISSON.DIST($E35,$C$27,FALSE)*POISSON.DIST(J$30,$C$28,FALSE) | K35: =POISSON.DIST($E35,$C$27,FALSE)*POISSON.DIST(K$30,$C$28,FALSE) | L35: =POISSON.DIST($E35,$C$27,FALSE)*POISSON.DIST(L$30,$C$28,FALSE) | M35: =POISSON.DIST($E35,$C$27,FALSE)*POISSON.DIST(M$30,$C$28,FALSE) | N35: =POISSON.DIST($E35,$C$27,FALSE)*POISSON.DIST(N$30,$C$28,FALSE)
E36: 5 | F36: =POISSON.DIST($E36,$C$27,FALSE)*POISSON.DIST(F$30,$C$28,FALSE) | G36: =POISSON.DIST($E36,$C$27,FALSE)*POISSON.DIST(G$30,$C$28,FALSE) | H36: =POISSON.DIST($E36,$C$27,FALSE)*POISSON.DIST(H$30,$C$28,FALSE) | I36: =POISSON.DIST($E36,$C$27,FALSE)*POISSON.DIST(I$30,$C$28,FALSE) | J36: =POISSON.DIST($E36,$C$27,FALSE)*POISSON.DIST(J$30,$C$28,FALSE) | K36: =POISSON.DIST($E36,$C$27,FALSE)*POISSON.DIST(K$30,$C$28,FALSE) | L36: =POISSON.DIST($E36,$C$27,FALSE)*POISSON.DIST(L$30,$C$28,FALSE) | M36: =POISSON.DIST($E36,$C$27,FALSE)*POISSON.DIST(M$30,$C$28,FALSE) | N36: =POISSON.DIST($E36,$C$27,FALSE)*POISSON.DIST(N$30,$C$28,FALSE)
E37: 6 | F37: =POISSON.DIST($E37,$C$27,FALSE)*POISSON.DIST(F$30,$C$28,FALSE) | G37: =POISSON.DIST($E37,$C$27,FALSE)*POISSON.DIST(G$30,$C$28,FALSE) | H37: =POISSON.DIST($E37,$C$27,FALSE)*POISSON.DIST(H$30,$C$28,FALSE) | I37: =POISSON.DIST($E37,$C$27,FALSE)*POISSON.DIST(I$30,$C$28,FALSE) | J37: =POISSON.DIST($E37,$C$27,FALSE)*POISSON.DIST(J$30,$C$28,FALSE) | K37: =POISSON.DIST($E37,$C$27,FALSE)*POISSON.DIST(K$30,$C$28,FALSE) | L37: =POISSON.DIST($E37,$C$27,FALSE)*POISSON.DIST(L$30,$C$28,FALSE) | M37: =POISSON.DIST($E37,$C$27,FALSE)*POISSON.DIST(M$30,$C$28,FALSE) | N37: =POISSON.DIST($E37,$C$27,FALSE)*POISSON.DIST(N$30,$C$28,FALSE)
E38: 7 | F38: =POISSON.DIST($E38,$C$27,FALSE)*POISSON.DIST(F$30,$C$28,FALSE) | G38: =POISSON.DIST($E38,$C$27,FALSE)*POISSON.DIST(G$30,$C$28,FALSE) | H38: =POISSON.DIST($E38,$C$27,FALSE)*POISSON.DIST(H$30,$C$28,FALSE) | I38: =POISSON.DIST($E38,$C$27,FALSE)*POISSON.DIST(I$30,$C$28,FALSE) | J38: =POISSON.DIST($E38,$C$27,FALSE)*POISSON.DIST(J$30,$C$28,FALSE) | K38: =POISSON.DIST($E38,$C$27,FALSE)*POISSON.DIST(K$30,$C$28,FALSE) | L38: =POISSON.DIST($E38,$C$27,FALSE)*POISSON.DIST(L$30,$C$28,FALSE) | M38: =POISSON.DIST($E38,$C$27,FALSE)*POISSON.DIST(M$30,$C$28,FALSE) | N38: =POISSON.DIST($E38,$C$27,FALSE)*POISSON.DIST(N$30,$C$28,FALSE)
E39: 8 | F39: =POISSON.DIST($E39,$C$27,FALSE)*POISSON.DIST(F$30,$C$28,FALSE) | G39: =POISSON.DIST($E39,$C$27,FALSE)*POISSON.DIST(G$30,$C$28,FALSE) | H39: =POISSON.DIST($E39,$C$27,FALSE)*POISSON.DIST(H$30,$C$28,FALSE) | I39: =POISSON.DIST($E39,$C$27,FALSE)*POISSON.DIST(I$30,$C$28,FALSE) | J39: =POISSON.DIST($E39,$C$27,FALSE)*POISSON.DIST(J$30,$C$28,FALSE) | K39: =POISSON.DIST($E39,$C$27,FALSE)*POISSON.DIST(K$30,$C$28,FALSE) | L39: =POISSON.DIST($E39,$C$27,FALSE)*POISSON.DIST(L$30,$C$28,FALSE) | M39: =POISSON.DIST($E39,$C$27,FALSE)*POISSON.DIST(M$30,$C$28,FALSE) | N39: =POISSON.DIST($E39,$C$27,FALSE)*POISSON.DIST(N$30,$C$28,FALSE)
E42: 0 | F42: =($C$7+$E42)-($C$8+F$30) | G42: =($C$7+$E42)-($C$8+G$30) | H42: =($C$7+$E42)-($C$8+H$30) | I42: =($C$7+$E42)-($C$8+I$30) | J42: =($C$7+$E42)-($C$8+J$30) | K42: =($C$7+$E42)-($C$8+K$30) | L42: =($C$7+$E42)-($C$8+L$30) | M42: =($C$7+$E42)-($C$8+M$30) | N42: =($C$7+$E42)-($C$8+N$30)
E43: 1 | F43: =($C$7+$E43)-($C$8+F$30) | G43: =($C$7+$E43)-($C$8+G$30) | H43: =($C$7+$E43)-($C$8+H$30) | I43: =($C$7+$E43)-($C$8+I$30) | J43: =($C$7+$E43)-($C$8+J$30) | K43: =($C$7+$E43)-($C$8+K$30) | L43: =($C$7+$E43)-($C$8+L$30) | M43: =($C$7+$E43)-($C$8+M$30) | N43: =($C$7+$E43)-($C$8+N$30)
E44: 2 | F44: =($C$7+$E44)-($C$8+F$30) | G44: =($C$7+$E44)-($C$8+G$30) | H44: =($C$7+$E44)-($C$8+H$30) | I44: =($C$7+$E44)-($C$8+I$30) | J44: =($C$7+$E44)-($C$8+J$30) | K44: =($C$7+$E44)-($C$8+K$30) | L44: =($C$7+$E44)-($C$8+L$30) | M44: =($C$7+$E44)-($C$8+M$30) | N44: =($C$7+$E44)-($C$8+N$30)
E45: 3 | F45: =($C$7+$E45)-($C$8+F$30) | G45: =($C$7+$E45)-($C$8+G$30) | H45: =($C$7+$E45)-($C$8+H$30) | I45: =($C$7+$E45)-($C$8+I$30) | J45: =($C$7+$E45)-($C$8+J$30) | K45: =($C$7+$E45)-($C$8+K$30) | L45: =($C$7+$E45)-($C$8+L$30) | M45: =($C$7+$E45)-($C$8+M$30) | N45: =($C$7+$E45)-($C$8+N$30)
E46: 4 | F46: =($C$7+$E46)-($C$8+F$30) | G46: =($C$7+$E46)-($C$8+G$30) | H46: =($C$7+$E46)-($C$8+H$30) | I46: =($C$7+$E46)-($C$8+I$30) | J46: =($C$7+$E46)-($C$8+J$30) | K46: =($C$7+$E46)-($C$8+K$30) | L46: =($C$7+$E46)-($C$8+L$30) | M46: =($C$7+$E46)-($C$8+M$30) | N46: =($C$7+$E46)-($C$8+N$30)
...

Sheet Ratings
A1: Team | B1: attack | C1: defence | E1: c | F1: 0.31544834 | H1: Hosts
A2: Algeria | B2: 0.6732 | C2: 0.6454 | E2: gamma(home) | F2: 0.2624369 | H2: United States | J2: Ratings exported from the fitted Dixon-Coles model (re-run scripts/build_excel.py after each daily refit to refresh).
A3: Argentina | B3: 1.0481 | C3: 1.3125 | H3: Mexico
A4: Australia | B4: 0.6393 | C4: 0.8167 | H4: Canada
A5: Austria | B5: 0.6287 | C5: 0.6771
A6: Belgium | B6: 0.9358 | C6: 0.8818
A7: Bosnia and Herzegovina | B7: 0.3313 | C7: 0.3856
A8: Brazil | B8: 1.1006 | C8: 1.2263
A9: Canada | B9: 0.6323 | C9: 0.7228
A10: Cape Verde | B10: 0.156 | C10: 0.4863
A11: Colombia | B11: 0.8986 | C11: 1.0655
A12: Croatia | B12: 0.7678 | C12: 0.7926
A13: Curaçao | B13: 0.1313 | C13: 0.1314
A14: Czech Republic | B14: 0.5274 | C14: 0.5664
A15: DR Congo | B15: 0.2694 | C15: 0.6197
A16: Ecuador | B16: 0.5703 | C16: 1.0024
... A49: Uzbekistan | B49: 0.3918 | C49: 0.6813

Sheet How to use
A1: HOW TO USE — 2026 World Cup Live Odds Calculator
A3: 1. Go to the 'Live Calculator' tab. Only type in the YELLOW cells.
A4: 2. Pick Home team and Away team from the dropdowns (use the same spelling as the model).
A5: 3. Enter the CURRENT score and the MINUTE (0 = kickoff, 94 = full time). As the game
A6: changes, update these and every number recalculates instantly.
A7: 4. Enter the live Polymarket prices as decimals (27¢ → 0.27) for Home win, Draw, Away win.
A8: Leave them at 0 to see the model-only view.
A9: 5. Read the GREEN cells: the blended fair probabilities, the big DRAW % box, and the verdict.
A11: WHAT THE NUMBERS MEAN
A12: • Model = the Dixon-Coles engine using the two teams + current score + minutes left.
A13: • Market = Polymarket's prices with the bookmaker margin removed ('de-vigged').
A14: • Blended = the two combined (default 60% market / 40% model) — your fair estimate.
... A26: • Bet responsibly and only what you can afford to lose.
